2017-12-04 00:44:47,275 INFO Informational message
2017-12-04 00:44:47,275 ERROR An error has happened!
2017-12-04 00:46:51,963 INFO Informational message
2017-12-04 00:46:51,963 ERROR An error has happened!
2017-12-04 00:47:03,958 INFO Informational message
2017-12-04 00:47:03,958 ERROR An error has happened!
2017-12-04 01:11:41,939 ERROR Internal Server Error: /facebot/chanels/2/delete/
Traceback (most recent call last):
  File "/home/maxim/work/botenv2/lib/python3.5/site-packages/django/core/handlers/exception.py", line 41, in inner
    response = get_response(request)
  File "/home/maxim/work/botenv2/lib/python3.5/site-packages/django/core/handlers/base.py", line 217, in _get_response
    response = self.process_exception_by_middleware(e, request)
  File "/home/maxim/work/botenv2/lib/python3.5/site-packages/django/core/handlers/base.py", line 215, in _get_response
    response = response.render()
  File "/home/maxim/work/botenv2/lib/python3.5/site-packages/django/template/response.py", line 107, in render
    self.content = self.rendered_content
  File "/home/maxim/work/botenv2/lib/python3.5/site-packages/django/template/response.py", line 82, in rendered_content
    template = self.resolve_template(self.template_name)
  File "/home/maxim/work/botenv2/lib/python3.5/site-packages/django/template/response.py", line 64, in resolve_template
    return select_template(template, using=self.using)
  File "/home/maxim/work/botenv2/lib/python3.5/site-packages/django/template/loader.py", line 53, in select_template
    raise TemplateDoesNotExist(', '.join(template_name_list), chain=chain)
django.template.exceptions.TemplateDoesNotExist: facebot/chanels_confirm_delete.html
